Workbook
Name Slicer_Category: #N/A
Name Slicer_Membership: #N/A
Name Slicer_Region: #N/A
Name Slicer_Sales_Channel: #N/A
Name Slicer_Transaction_Date__Month: #N/A

Sheet Customers
A1: Customer_ID | B1: Customer_Name | C1: Gender | D1: DOB | E1: Phone | F1: Email | G1: City | H1: State | I1: Region | J1: Membership | K1: Registration_Date
A2: CUST0001 | B2: Revathi Balan | C2: Female | D2: 31272 | E2: 9204528821 | F2: revathi1@gmail.com | G2: Coimbatore | H2: Tamil Nadu | I2: South | J2: Bronze | K2: 44659
A3: CUST0002 | B3: Eswari Murugan | C3: Female | D3: 21939 | E3: 9362238769 | F3: eswari2@gmail.com | G3: Tiruppur | H3: Tamil Nadu | I3: South | J3: Silver | K3: 45809
A4: CUST0003 | B4: Banu Balan | C4: Female | D4: 22236 | E4: 9222912620 | F4: banu3@gmail.com | G4: Erode | H4: Tamil Nadu | I4: South | J4: Bronze | K4: 44349
A5: CUST0004 | B5: Naveen Sharma | C5: Male | D5: 21314 | E5: 9806272779 | F5: naveen4@gmail.com | G5: Coimbatore | H5: Tamil Nadu | I5: South | J5: Silver | K5: 44988
A6: CUST0005 | B6: Pandi Raj | C6: Male | D6: 35481 | E6: 9123876200 | F6: pandi5@gmail.com | G6: Guwahati | H6: Assam | I6: East | J6: Silver | K6: 45509
A7: CUST0006 | B7: Thiru Devi | C7: Male | D7: 38850 | E7: 9967934041 | F7: thiru6@gmail.com | G7: Kanpur | H7: Uttar Pradesh | I7: North | J7: Silver | K7: 43501
A8: CUST0007 | B8: Senthil Pillai | C8: Male | D8: 36564 | E8: 9464577685 | F8: senthil7@gmail.com | G8: Salem | H8: Tamil Nadu | I8: South | J8: Silver | K8: 45834
A9: CUST0008 | B9: Eswari Raj | C9: Female | D9: 34376 | E9: 9633597839 | F9: eswari8@gmail.com | G9: Erode | H9: Tamil Nadu | I9: South | J9: Silver | K9: 43927
A10: CUST0009 | B10: Mani Nair | C10: Male | D10: 37648 | E10: 9408545686 | F10: mani9@gmail.com | G10: Chennai | H10: Tamil Nadu | I10: South | J10: Bronze | K10: 43977
A11: CUST0010 | B11: Tara Achari | C11: Female | D11: 33263 | E11: 9770629385 | F11: tara10@gmail.com | G11: Erode | H11: Tamil Nadu | I11: South | J11: Bronze | K11: 44026
A12: CUST0011 | B12: Prasath Mudaliar | C12: Male | D12: 39036 | E12: 9735509839 | F12: prasath11@gmail.com | G12: Chennai | H12: Tamil Nadu | I12: South | J12: Bronze | K12: 43489
A13: CUST0012 | B13: Meena Gupta | C13: Female | D13: 37491 | E13: 9558601461 | F13: meena12@gmail.com | G13: Chennai | H13: Tamil Nadu | I13: South | J13: Bronze | K13: 45047
... A701: CUST0700 | B701: Radha Naicker | C701: Female | D701: 21870 | E701: 9158725903 | F701: radha700@gmail.com | G701: Kochi | H701: Kerala | I701: South | J701: Silver | K701: 43447

Sheet Employees
A1: Employee_ID | B1: Employee_Name | C1: Gender | D1: Department | E1: Salary | F1: Joining_Date | G1: Store_ID | H1: Employment_Status
A2: EMP0001 | B2: Manoj Pillai | C2: Male | D2: Sales | E2: 25521 | F2: 44189 | G2: STR147 | H2: Active
A3: EMP0002 | B3: Lokesh Gounder | C3: Male | D3: Billing | E3: 24166 | F3: 44201 | G3: STR081 | H3: Active
A4: EMP0003 | B4: Manoj Achari | C4: Male | D4: Sales | E4: 26148 | F4: 45422 | G4: STR168 | H4: Active
A5: EMP0004 | B5: Hema Chettiar | C5: Female | D5: Sales | E5: 24609 | F5: 44058 | G5: STR010 | H5: Active
A6: EMP0005 | B6: Harini Sekar | C6: Female | D6: Inventory | E6: 17002 | F6: 45752 | G6: STR024 | H6: Active
A7: EMP0006 | B7: Indira Nair | C7: Female | D7: Cashier | E7: 21890 | F7: 44905 | G7: STR164 | H7: Active
A8: EMP0007 | B8: Udhay Selvam | C8: Male | D8: Billing | E8: 24328 | F8: 44673 | G8: STR053 | H8: Active
A9: EMP0008 | B9: Karthik Balan | C9: Male | D9: Store Manager | E9: 59949 | F9: 43766 | G9: STR094 | H9: Active
A10: EMP0009 | B10: Usha Chettiar | C10: Female | D10: Cashier | E10: 20689 | F10: 43283 | G10: STR117 | H10: Active
A11: EMP0010 | B11: Hema Sharma | C11: Female | D11: Billing | E11: 25829 | F11: 44307 | G11: STR169 | H11: Active
A12: EMP0011 | B12: Balamurugan Sharma | C12: Male | D12: Billing | E12: 23414 | F12: 42837 | G12: STR025 | H12: Active
A13: EMP0012 | B13: Suresh Nathan | C13: Male | D13: Cashier | E13: 15816 | F13: 42378 | G13: STR088 | H13: Active
... A351: EMP0350 | B351: Uma Pandian | C351: Female | D351: Cashier | E351: 20357 | F351: 44910 | G351: STR062 | H351: Active

Sheet Products
A1: Product_ID | B1: Product_Name | C1: Category | D1: Subcategory | E1: Brand | F1: Cost_Price | G1: Selling_Price | H1: Supplier_ID | I1: Season | J1: Status
A2: PRD001 | B2: Local Bakers Buns 1kg | C2: Bakery | D2: Buns | E2: Local Bakers | F2: 184.74 | G2: 299.73 | H2: SUP059 | I2: Summer | J2: Active
A3: PRD002 | B3: Britannia Buns Pack | C3: Bakery | D3: Buns | E3: Britannia | F3: 254.05 | G3: 440.5 | H3: SUP062 | I3: Monsoon | J3: Active
A4: PRD003 | B4: Harvest Gold Buns Combo | C4: Bakery | D4: Buns | E4: Harvest Gold | F4: 343.65 | G4: 589.75 | H4: SUP012 | I4: Winter | J4: Active
A5: PRD004 | B5: Britannia Buns 2kg | C5: Bakery | D5: Buns | E5: Britannia | F5: 236.54 | G5: 398.25 | H5: SUP044 | I5: All Season | J5: Active
A6: PRD005 | B6: Amul Paneer 250ml | C6: Bakery | D6: Buns | E6: Harvest Gold | F6: 205.27 | G6: 332.74 | H6: SUP034 | I6: Winter | J6: Active
A7: PRD006 | B7: Harvest Gold Cookies 500g | C7: Bakery | D7: Cookies | E7: Harvest Gold | F7: 216.32 | G7: 343.56 | H7: SUP031 | I7: Monsoon | J7: Active
A8: PRD007 | B8: Britannia Buns 2kg v2 | C8: Bakery | D8: Buns | E8: Britannia | F8: 265.44 | G8: 437.49 | H8: SUP003 | I8: All Season | J8: Active
A9: PRD008 | B9: Britannia Cookies 200g | C9: Bakery | D9: Cookies | E9: Britannia | F9: 282.88 | G9: 455.79 | H9: SUP075 | I9: Winter | J9: Active
A10: PRD009 | B10: Harvest Gold Buns 200g | C10: Bakery | D10: Buns | E10: Harvest Gold | F10: 398.72 | G10: 661.91 | H10: SUP046 | I10: Monsoon | J10: Active
A11: PRD010 | B11: Harvest Gold Cookies Pack | C11: Bakery | D11: Cookies | E11: Harvest Gold | F11: 107.6 | G11: 182.3 | H11: SUP041 | I11: All Season | J11: Active
A12: PRD011 | B12: Britannia Rusk 1L | C12: Bakery | D12: Rusk | E12: Britannia | F12: 102.23 | G12: 168.36 | H12: SUP076 | I12: Festive | J12: Active
A13: PRD012 | B13: Harvest Gold Rusk 1kg | C13: Bakery | D13: Rusk | E13: Harvest Gold | F13: 336.4 | G13: 541.35 | H13: SUP047 | I13: Summer | J13: Active
... A151: PRD150 | B151: Lizol Toilet Cleaner 200g v2 | C151: Cleaning | D151: Toilet Cleaner | E151: Lizol | F151: 158.06 | G151: 214.04 | H151: SUP021 | I151: All Season | J151: Active

Sheet Stores
A1: Store_ID | B1: Store_Name | C1: Manager | D1: Region | E1: City | F1: State | G1: Store_Type | H1: Opening_Date | I1: Monthly_Target | J1: Status
A2: STR001 | B2: FreshMart Madurai Crossing | C2: Sudha Naicker | D2: South | E2: Madurai | F2: Tamil Nadu | G2: Supermarket | H2: 42147 | I2: 1921769 | J2: Active
A3: STR002 | B3: FreshMart Tiruppur Bypass | C3: Manoj Nair | D3: South | E3: Tiruppur | F3: Tamil Nadu | G3: Convenience | H3: 42633 | I3: 591044 | J3: Active
A4: STR003 | B4: FreshMart Tiruppur Square | C4: Suresh Nathan | D4: South | E4: Tiruppur | F4: Tamil Nadu | G4: Express | H4: 44173 | I4: 890380 | J4: Active
A5: STR004 | B5: FreshMart Erode Plaza | C5: Prakash Kumar | D5: South | E5: Erode | F5: Tamil Nadu | G5: Convenience | H5: 44049 | I5: 584869 | J5: Active
A6: STR005 | B6: FreshMart Chennai Crossing | C6: Lokesh Mudaliar | D6: South | E6: Chennai | F6: Tamil Nadu | G6: Express | H6: 42883 | I6: 983603 | J6: Active
A7: STR006 | B7: FreshMart Mysuru Junction | C7: Senthil Sekar | D7: South | E7: Mysuru | F7: Karnataka | G7: Supermarket | H7: 43856 | I7: 2561982 | J7: Active
A8: STR007 | B8: FreshMart Mysuru Towers | C8: Sudha Sekar | D8: South | E8: Mysuru | F8: Karnataka | G8: Express | H8: 44740 | I8: 988505 | J8: Active
A9: STR008 | B9: FreshMart Kochi Plaza | C9: Malathi Sekar | D9: South | E9: Kochi | F9: Kerala | G9: Supermarket | H9: 44920 | I9: 2481146 | J9: Active
A10: STR009 | B10: FreshMart Kochi Square | C10: Hari Naicker | D10: South | E10: Kochi | F10: Kerala | G10: Convenience | H10: 42974 | I10: 429599 | J10: Active
A11: STR010 | B11: FreshMart Kochi Colony | C11: Bhuvana Naicker | D11: South | E11: Kochi | F11: Kerala | G11: Hypermarket | H11: 42536 | I11: 3928553 | J11: Active
A12: STR011 | B12: FreshMart Bengaluru Enclave | C12: Vasanthi Chandran | D12: South | E12: Bengaluru | F12: Karnataka | G12: Convenience | H12: 43687 | I12: 569084 | J12: Active
A13: STR012 | B13: FreshMart Chennai Junction | C13: Pandi Varma | D13: South | E13: Chennai | F13: Tamil Nadu | G13: Convenience | H13: 43848 | I13: 544019 | J13: Active
... A181: STR180 | B181: FreshMart Guwahati Extension | C181: Suresh Naidu | D181: East | E181: Guwahati | F181: Assam | G181: Hypermarket | H181: 44575 | I181: 4606432 | J181: Active

Sheet Suppliers
A1: Supplier_ID | B1: Supplier_Name | C1: Contact_Person | D1: Phone | E1: Email | F1: City | G1: Lead_Time_Days | H1: Rating | I1: Status
A2: SUP001 | B2: Anna Agro Pvt Ltd | C2: Madhavan Rao | D2: 9826600539 | E2: madhavan.anna@agromail.com | F2: Salem | G2: 4 | H2: 4.3 | I2: Active
A3: SUP002 | B3: Palani Suppliers Pvt Ltd | C3: Kamala Subramaniam | D3: 9349817734 | E3: kamala.palani@suppliersmail.com | F3: Coimbatore | G3: 2 | H3: 2.7 | I3: Active
A4: SUP003 | B4: Saravana Beverages Pvt Ltd | C4: Hari Mudaliar | D4: 9732719211 | E4: hari.saravana@beveragesmail.com | F4: Kochi | G4: 8 | H4: 3.1 | I4: Active
A5: SUP004 | B5: Coastal Household Products Pvt Ltd | C5: Aishwarya Naicker | D5: 9398362082 | E5: aishwarya.coastal@householdmail.com | F5: Madurai | G5: 13 | H5: 3.6 | I5: Active
A6: SUP005 | B6: Vel Traders Pvt Ltd | C6: Padma Raj | D6: 9469319644 | E6: padma.vel@bizcom | F6: Chennai | G6: 8 | H6: 2.7 | I6: Active
A7: SUP006 | B7: Kovai Distributors Pvt Ltd | C7: Vasanthi Venkataraman | D7: 9506448196 | E7: vasanthi.kovai@distributorsmail.com | F7: Kochi | G7: 45 | H7: 4.9 | I7: Active
A8: SUP007 | B8: Om Fresh Produce Pvt Ltd | C8: Raghav Prabhu | D8: 9174684276 | E8: raghav.om@freshmail.com | F8: Tiruppur | G8: 11 | H8: 3 | I8: Active
A9: SUP008 | B9: Sree Snacks Co Pvt Ltd | C9: Naveen Devi | D9: 9398471886 | E9: naveen.sree@snacksmail.com | F9: Salem | G9: 15 | H9: 2.8 | I9: Active
A10: SUP009 | B10: Ganesh Snacks Co Pvt Ltd | C10: Chitra Gupta | D10: 9853573823 | E10: chitra.ganesh@snacksmail.com | F10: Tiruppur | G10: 5 | H10: 4.2 | I10: Active
A11: SUP010 | B11: Bharat Snacks Co Pvt Ltd | C11: Raghav Pillai | D11: 9596348124 | E11: raghav.bharat@snacksmail.com | F11: Kochi | G11: 13 | H11: 3.1 | I11: Active
A12: SUP011 | B12: Malabar Distributors Pvt Ltd | C12: Nandhini Mudaliar | D12: 9924970419 | E12: nandhini.malabar@distributorsmail.com | F12: Kochi | G12: 5 | H12: 4.2 | I12: Active
A13: SUP012 | B13: Tirupati Foods Pvt Ltd | C13: Karthik Naicker | D13: 9326541099 | E13: karthik.tirupati@foodsmail.com | F13: Tiruppur | G13: 8 | H13: 3.2 | I13: Active
... A86: SUP085 | B86: Anna Traders Pvt Ltd | C86: Ezhil Menon | D86: 9707665448 | E86: ezhil.anna@tradersmail.com | F86: Hyderabad | G86: 14 | H86: 2.8 | I86: Active

Sheet Sales_Transactions
A1: Invoice_Number | B1: Transaction_Date | C1: Customer_ID | D1: Customer_Name | E1: Membership | F1: Product_ID | G1: Product_Name | H1: Category | I1: Store_ID | J1: Store_Name | K1: Region | L1: Employee_ID | M1: Employee_Name | N1: Department | O1: Quantity | P1: Unit_Price | Q1: Discount_Pct | R1: Discount_Amount | S1: Sales_Amount | T1: Cost_Amount | U1: Profit | V1: Payment_Mode | W1: Return_Status | X1: Sales_Channel | Y1: Order_Time | Z1: Day_Type
A2: INV100001 | B2: 45836 | C2: CUST0525 | D2: =IFERROR(INDEX(Customers!$B:$B,MATCH(C2,Customers!$A:$A,0)),"") -> Sudha Gupta | E2: =IFERROR(INDEX(Customers!$J:$J,MATCH(C2,Customers!$A:$A,0)),"") -> Bronze | F2: PRD138 | G2: =IFERROR(INDEX(Products!$B:$B,MATCH(F2,Products!$A:$A,0)),"") -> MDH Whole Spices Combo | H2: =IFERROR(INDEX(Products!$C:$C,MATCH(F2,Products!$A:$A,0)),"") -> Masala | I2: STR051 | J2: =IFERROR(INDEX(Stores!$B:$B,MATCH(I2,Stores!$A:$A,0)),"") -> FreshMart Madurai Arcade | K2: =IFERROR(INDEX(Stores!$D:$D,MATCH(I2,Stores!$A:$A,0)),"") -> South | L2: EMP0333 | M2: =IFERROR(INDEX(Employees!$B:$B,MATCH(L2,Employees!$A:$A,0)),"") -> Vasanthi Velan | N2: =IFERROR(INDEX(Employees!$D:$D,MATCH(L2,Employees!$A:$A,0)),"") -> Cashier | O2: 1 | P2: 416.08 | Q2: 0 | R2: 0 | S2: 478.49 | T2: 319.64 | U2: 158.85 | V2: Wallet | W2: Not Returned | X2: In-Store | Y2: 20:03 | Z2: Weekend
A3: INV100002 | B3: 46103 | C3: CUST0114 | D3: =IFERROR(INDEX(Customers!$B:$B,MATCH(C3,Customers!$A:$A,0)),"") -> Hariharan Menon | E3: =IFERROR(INDEX(Customers!$J:$J,MATCH(C3,Customers!$A:$A,0)),"") -> Bronze | F3: PRD019 | G3: =IFERROR(INDEX(Products!$B:$B,MATCH(F3,Products!$A:$A,0)),"") -> Amul Paneer 1kg | H3: =IFERROR(INDEX(Products!$C:$C,MATCH(F3,Products!$A:$A,0)),"") -> Dairy | I3: STR082 | J3: =IFERROR(INDEX(Stores!$B:$B,MATCH(I3,Stores!$A:$A,0)),"") -> FreshMart Salem Bypass | K3: =IFERROR(INDEX(Stores!$D:$D,MATCH(I3,Stores!$A:$A,0)),"") -> South | L3: EMP0115 | M3: =IFERROR(INDEX(Employees!$B:$B,MATCH(L3,Employees!$A:$A,0)),"") -> Vasanth Menon | N3: =IFERROR(INDEX(Employees!$D:$D,MATCH(L3,Employees!$A:$A,0)),"") -> Store Manager | O3: 2 | P3: 448.94 | Q3: 0 | R3: 0 | S3: 1032.56 | T3: 760.16 | U3: 272.4 | V3: Wallet | W3: Not Returned | X3: Mobile App | Y3: 09:51 | Z3: Weekend
A4: INV100003 | B4: 45920 | C4: CUST0438 | D4: =IFERROR(INDEX(Customers!$B:$B,MATCH(C4,Customers!$A:$A,0)),"") -> Nandhini Mudaliar | E4: =IFERROR(INDEX(Customers!$J:$J,MATCH(C4,Customers!$A:$A,0)),"") -> Bronze | F4: PRD119 | G4: =IFERROR(INDEX(Products!$B:$B,MATCH(F4,Products!$A:$A,0)),"") -> Gold Winner Sunflower Oil 200g | H4: =IFERROR(INDEX(Products!$C:$C,MATCH(F4,Products!$A:$A,0)),"") -> Oil | I4: STR008 | J4: =IFERROR(INDEX(Stores!$B:$B,MATCH(I4,Stores!$A:$A,0)),"") -> FreshMart Kochi Plaza | K4: =IFERROR(INDEX(Stores!$D:$D,MATCH(I4,Stores!$A:$A,0)),"") -> South | L4: EMP0249 | M4: =IFERROR(INDEX(Employees!$B:$B,MATCH(L4,Employees!$A:$A,0)),"") -> Radha Murugan | N4: =IFERROR(INDEX(Employees!$D:$D,MATCH(L4,Employees!$A:$A,0)),"") -> Inventory | O4: 1 | P4: 234.86 | Q4: 10 | R4: 23.49 | S4: 243.08 | T4: 213.23 | U4: 29.85 | V4: Cash | W4: Not Returned | X4: In-Store | Y4: 09:53 | Z4: Weekend
A5: INV100004 | B5: 45848 | C5: CUST0680 | D5: =IFERROR(INDEX(Customers!$B:$B,MATCH(C5,Customers!$A:$A,0)),"") -> Lokesh Chandran | E5: =IFERROR(INDEX(Customers!$J:$J,MATCH(C5,Customers!$A:$A,0)),"") -> Silver | F5: PRD004 | G5: =IFERROR(INDEX(Products!$B:$B,MATCH(F5,Products!$A:$A,0)),"") -> Britannia Buns 2kg | H5: =IFERROR(INDEX(Products!$C:$C,MATCH(F5,Products!$A:$A,0)),"") -> Bakery | I5: STR100 | J5: =IFERROR(INDEX(Stores!$B:$B,MATCH(I5,Stores!$A:$A,0)),"") -> FreshMart Ahmedabad Enclave | K5: =IFERROR(INDEX(Stores!$D:$D,MATCH(I5,Stores!$A:$A,0)),"") -> West | L5: EMP0324 | M5: =IFERROR(INDEX(Employees!$B:$B,MATCH(L5,Employees!$A:$A,0)),"") -> Devi Raj | N5: =IFERROR(INDEX(Employees!$D:$D,MATCH(L5,Employees!$A:$A,0)),"") -> Inventory | O5: 2 | P5: 398.25 | Q5: 20 | R5: 159.3 | S5: 637.2 | T5: 473.08 | U5: 164.12 | V5: Credit Card | W5: Not Returned | X5: In-Store | Y5: 18:43 | Z5: Weekday
A6: INV100005 | B6: 45844 | C6: CUST0137 | D6: =IFERROR(INDEX(Customers!$B:$B,MATCH(C6,Customers!$A:$A,0)),"") -> Raghav Selvam | E6: =IFERROR(INDEX(Customers!$J:$J,MATCH(C6,Customers!$A:$A,0)),"") -> Gold | F6: PRD024 | G6: =IFERROR(INDEX(Products!$B:$B,MATCH(F6,Products!$A:$A,0)),"") -> Aavin Milk Pack v2 | H6: =IFERROR(INDEX(Products!$C:$C,MATCH(F6,Products!$A:$A,0)),"") -> Dairy | I6: STR127 | J6: =IFERROR(INDEX(Stores!$B:$B,MATCH(I6,Stores!$A:$A,0)),"") -> FreshMart Surat Enclave | K6: =IFERROR(INDEX(Stores!$D:$D,MATCH(I6,Stores!$A:$A,0)),"") -> West | L6: EMP0225 | M6: =IFERROR(INDEX(Employees!$B:$B,MATCH(L6,Employees!$A:$A,0)),"") -> Banu Achari | N6: =IFERROR(INDEX(Employees!$D:$D,MATCH(L6,Employees!$A:$A,0)),"") -> Sales | O6: 4 | P6: 351.96 | Q6: 15 | R6: 211.18 | S6: 1376.16 | T6: 984.48 | U6: 391.68 | V6: Credit Card | W6: Not Returned | X6: Online | Y6: 17:12 | Z6: Weekend
A7: INV100006 | B7: 45827 | C7: CUST0384 | D7: =IFERROR(INDEX(Customers!$B:$B,MATCH(C7,Customers!$A:$A,0)),"") -> Anand Kumar | E7: =IFERROR(INDEX(Customers!$J:$J,MATCH(C7,Customers!$A:$A,0)),"") -> Gold | F7: PRD031 | G7: =IFERROR(INDEX(Products!$B:$B,MATCH(F7,Products!$A:$A,0)),"") -> Nescafe Coffee Pack | H7: =IFERROR(INDEX(Products!$C:$C,MATCH(F7,Products!$A:$A,0)),"") -> Beverages | I7: STR025 | J7: =IFERROR(INDEX(Stores!$B:$B,MATCH(I7,Stores!$A:$A,0)),"") -> FreshMart Tiruppur Enclave | K7: =IFERROR(INDEX(Stores!$D:$D,MATCH(I7,Stores!$A:$A,0)),"") -> South | L7: EMP0281 | M7: =IFERROR(INDEX(Employees!$B:$B,MATCH(L7,Employees!$A:$A,0)),"") -> Malathi Iyer | N7: =IFERROR(INDEX(Employees!$D:$D,MATCH(L7,Employees!$A:$A,0)),"") -> Sales | O7: 8 | P7: 356.6 | Q7: 5 | R7: 142.64 | S7: 2710.16 | T7: 2174.24 | U7: 535.92 | V7: Wallet | W7: Not Returned | X7: In-Store | Y7: 15:09 | Z7: Weekday
A8: INV100007 | B8: 45857 | C8: CUST0447 | D8: =IFERROR(INDEX(Customers!$B:$B,MATCH(C8,Customers!$A:$A,0)),"") -> Harini Krishnan | E8: =IFERROR(INDEX(Customers!$J:$J,MATCH(C8,Customers!$A:$A,0)),"") -> Bronze | F8: PRD030 | G8: =IFERROR(INDEX(Products!$B:$B,MATCH(F8,Products!$A:$A,0)),"") -> Nescafe Tea Combo | H8: =IFERROR(INDEX(Products!$C:$C,MATCH(F8,Products!$A:$A,0)),"") -> Beverages | I8: STR059 | J8: =IFERROR(INDEX(Stores!$B:$B,MATCH(I8,Stores!$A:$A,0)),"") -> FreshMart Coimbatore Plaza | K8: =IFERROR(INDEX(Stores!$D:$D,MATCH(I8,Stores!$A:$A,0)),"") -> South | L8: EMP0015 | M8: =IFERROR(INDEX(Employees!$B:$B,MATCH(L8,Employees!$A:$A,0)),"") -> Harini Krishnan | N8: =IFERROR(INDEX(Employees!$D:$D,MATCH(L8,Employees!$A:$A,0)),"") -> Inventory | O8: 4 | P8: 172.63 | Q8: 0 | R8: 0 | S8: 794.1 | T8: 568 | U8: 226.1 | V8: Net Banking | W8: Not Returned | X8: In-Store | Y8: 19:39 | Z8: Weekend
A9: INV100008 | B9: 46110 | C9: CUST0267 | D9: =IFERROR(INDEX(Customers!$B:$B,MATCH(C9,Customers!$A:$A,0)),"") -> Manoj Gounder | E9: =IFERROR(INDEX(Customers!$J:$J,MATCH(C9,Customers!$A:$A,0)),"") -> Silver | F9: PRD030 | G9: =IFERROR(INDEX(Products!$B:$B,MATCH(F9,Products!$A:$A,0)),"") -> Nescafe Tea Combo | H9: =IFERROR(INDEX(Products!$C:$C,MATCH(F9,Products!$A:$A,0)),"") -> Beverages | I9: STR019 | J9: =IFERROR(INDEX(Stores!$B:$B,MATCH(I9,Stores!$A:$A,0)),"") -> FreshMart Hyderabad Heights | K9: =IFERROR(INDEX(Stores!$D:$D,MATCH(I9,Stores!$A:$A,0)),"") -> South | L9: EMP0273 | M9: =IFERROR(INDEX(Employees!$B:$B,MATCH(L9,Employees!$A:$A,0)),"") -> Prasath Subramaniam | N9: =IFERROR(INDEX(Employees!$D:$D,MATCH(L9,Employees!$A:$A,0)),"") -> Store Manager | O9: 4 | P9: 172.63 | Q9: 0 | R9: 0 | S9: 794.1 | T9: 568 | U9: 226.1 | V9: Cash | W9: Not Returned | X9: In-Store | Y9: 17:13 | Z9: Weekend
A10: INV100009 | B10: 45893 | C10: CUST0151 | D10: =IFERROR(INDEX(Customers!$B:$B,MATCH(C10,Customers!$A:$A,0)),"") -> Gopal Selvam | E10: =IFERROR(INDEX(Customers!$J:$J,MATCH(C10,Customers!$A:$A,0)),"") -> Silver | F10: PRD105 | G10: =IFERROR(INDEX(Products!$B:$B,MATCH(F10,Products!$A:$A,0)),"") -> India Gate Basmati Rice 250ml | H10: =IFERROR(INDEX(Products!$C:$C,MATCH(F10,Products!$A:$A,0)),"") -> Rice | I10: STR062 | J10: =IFERROR(INDEX(Stores!$B:$B,MATCH(I10,Stores!$A:$A,0)),"") -> FreshMart Hyderabad Crossing | K10: =IFERROR(INDEX(Stores!$D:$D,MATCH(I10,Stores!$A:$A,0)),"") -> South | L10: EMP0350 | M10: =IFERROR(INDEX(Employees!$B:$B,MATCH(L10,Employees!$A:$A,0)),"") -> Uma Pandian | N10: =IFERROR(INDEX(Employees!$D:$D,MATCH(L10,Employees!$A:$A,0)),"") -> Cashier | O10: 5 | P10: 131.03 | Q10: 0 | R10: 0 | S10: 753.42 | T10: 586.35 | U10: 167.07 | V10: UPI | W10: Not Returned | X10: Online | Y10: 13:50 | Z10: Weekend
A11: INV100010 | B11: 45807 | C11: CUST0041 | D11: =IFERROR(INDEX(Customers!$B:$B,MATCH(C11,Customers!$A:$A,0)),"") -> Geetha Iyer | E11: =IFERROR(INDEX(Customers!$J:$J,MATCH(C11,Customers!$A:$A,0)),"") -> Silver | F11: PRD079 | G11: =IFERROR(INDEX(Products!$B:$B,MATCH(F11,Products!$A:$A,0)),"") -> Eveready Detergent Pack | H11: =IFERROR(INDEX(Products!$C:$C,MATCH(F11,Products!$A:$A,0)),"") -> Household | I11: STR071 | J11: =IFERROR(INDEX(Stores!$B:$B,MATCH(I11,Stores!$A:$A,0)),"") -> FreshMart Salem Crossing | K11: =IFERROR(INDEX(Stores!$D:$D,MATCH(I11,Stores!$A:$A,0)),"") -> South | L11: EMP0189 | M11: =IFERROR(INDEX(Employees!$B:$B,MATCH(L11,Employees!$A:$A,0)),"") -> Harini Pillai | N11: =IFERROR(INDEX(Employees!$D:$D,MATCH(L11,Employees!$A:$A,0)),"") -> Billing | O11: 4 | P11: 260.93 | Q11: 5 | R11: 52.19 | S11: 991.53 | T11: 776.24 | U11: 215.29 | V11: UPI | W11: Not Returned | X11: In-Store | Y11: 20:59 | Z11: Weekday
A12: INV100011 | B12: 45980 | C12: UNKNOWN | D12: =IFERROR(INDEX(Customers!$B:$B,MATCH(C12,Customers!$A:$A,0)),"") | E12: =IFERROR(INDEX(Customers!$J:$J,MATCH(C12,Customers!$A:$A,0)),"") | F12: PRD021 | G12: =IFERROR(INDEX(Products!$B:$B,MATCH(F12,Products!$A:$A,0)),"") -> Milky Mist Butter Pack | H12: =IFERROR(INDEX(Products!$C:$C,MATCH(F12,Products!$A:$A,0)),"") -> Dairy | I12: STR084 | J12: =IFERROR(INDEX(Stores!$B:$B,MATCH(I12,Stores!$A:$A,0)),"") -> FreshMart Tiruppur Market | K12: =IFERROR(INDEX(Stores!$D:$D,MATCH(I12,Stores!$A:$A,0)),"") -> South | L12: EMP0288 | M12: =IFERROR(INDEX(Employees!$B:$B,MATCH(L12,Employees!$A:$A,0)),"") -> Chitra Selvam | N12: =IFERROR(INDEX(Employees!$D:$D,MATCH(L12,Employees!$A:$A,0)),"") -> Sales | O12: 5 | P12: 42.05 | Q12: 20 | R12: 42.05 | S12: 168.2 | T12: 162 | U12: 6.2 | V12: UPI | W12: Not Returned | X12: In-Store | Y12: 20:10 | Z12: Weekday
A13: INV100012 | B13: 46092 | C13: CUST0574 | D13: =IFERROR(INDEX(Customers!$B:$B,MATCH(C13,Customers!$A:$A,0)),"") -> Dhanush Nathan | E13: =IFERROR(INDEX(Customers!$J:$J,MATCH(C13,Customers!$A:$A,0)),"") -> Bronze | F13: PRD142 | G13: =IFERROR(INDEX(Products!$B:$B,MATCH(F13,Products!$A:$A,0)),"") -> Lizol Dishwash 200g | H13: =IFERROR(INDEX(Products!$C:$C,MATCH(F13,Products!$A:$A,0)),"") -> Cleaning | I13: STR158 | J13: =IFERROR(INDEX(Stores!$B:$B,MATCH(I13,Stores!$A:$A,0)),"") -> FreshMart Delhi Crossing | K13: =IFERROR(INDEX(Stores!$D:$D,MATCH(I13,Stores!$A:$A,0)),"") -> North | L13: EMP0107 | M13: =IFERROR(INDEX(Employees!$B:$B,MATCH(L13,Employees!$A:$A,0)),"") -> Sangeetha Devi | N13: =IFERROR(INDEX(Employees!$D:$D,MATCH(L13,Employees!$A:$A,0)),"") -> Sales | O13: 2 | P13: 522.78 | Q13: 0 | R13: 0 | S13: 1045.56 | T13: 791.74 | U13: 253.82 | V13: Credit Card | W13: Not Returned | X13: In-Store | Y13: 15:59 | Z13: Weekday
... A844: INV100843 | B844: 45963 | C844: CUST0008 | D844: =IFERROR(INDEX(Customers!$B:$B,MATCH(C844,Customers!$A:$A,0)),"") -> Eswari Raj | E844: =IFERROR(INDEX(Customers!$J:$J,MATCH(C844,Customers!$A:$A,0)),"") -> Silver | F844: PRD139 | G844: =IFERROR(INDEX(Products!$B:$B,MATCH(F844,Products!$A:$A,0)),"") -> Lizol Toilet Cleaner Combo | H844: =IFERROR(INDEX(Products!$C:$C,MATCH(F844,Products!$A:$A,0)),"") -> Cleaning | I844: STR029 | J844: =IFERROR(INDEX(Stores!$B:$B,MATCH(I844,Stores!$A:$A,0)),"") -> FreshMart Bengaluru Colony | K844: =IFERROR(INDEX(Stores!$D:$D,MATCH(I844,Stores!$A:$A,0)),"") -> South | L844: EMP0063 | M844: =IFERROR(INDEX(Employees!$B:$B,MATCH(L844,Employees!$A:$A,0)),"") -> Lakshmi Devi | N844: =IFERROR(INDEX(Employees!$D:$D,MATCH(L844,Employees!$A:$A,0)),"") -> Store Manager | O844: 2 | P844: 91.61 | Q844: 0 | R844: 0 | S844: 210.7 | T844: 141.4 | U844: 69.3 | V844: Credit Card | W844: Not Returned | X844: In-Store | Y844: 10:57 | Z844: Weekend
A845: INV100844 | B845: 45996 | C845: CUST0589 | D845: =IFERROR(INDEX(Customers!$B:$B,MATCH(C845,Customers!$A:$A,0)),"") -> Ovi Venkataraman | E845: =IFERROR(INDEX(Customers!$J:$J,MATCH(C845,Customers!$A:$A,0)),"") -> Silver | F845: PRD091 | G845: =IFERROR(INDEX(Products!$B:$B,MATCH(F845,Products!$A:$A,0)),"") -> Local Farm Fresh Fruits 250ml | H845: =IFERROR(INDEX(Products!$C:$C,MATCH(F845,Products!$A:$A,0)),"") -> Fruits | I845: UNKNOWN | J845: =IFERROR(INDEX(Stores!$B:$B,MATCH(I845,Stores!$A:$A,0)),"") | K845: South | L845: EMP0244 | M845: =IFERROR(INDEX(Employees!$B:$B,MATCH(L845,Employees!$A:$A,0)),"") -> Udhay Chettiar | N845: =IFERROR(INDEX(Employees!$D:$D,MATCH(L845,Employees!$A:$A,0)),"") -> Cashier | O845: 1 | P845: 376.11 | Q845: 0 | R845: 0 | S845: 376.11 | T845: 301.57 | U845: 74.54 | V845: Wallet | W845: Not Returned | X845: Online | Y845: 15:36 | Z845: Weekday
A846: INV100845 | B846: 45788 | C846: CUST0529 | D846: =IFERROR(INDEX(Customers!$B:$B,MATCH(C846,Customers!$A:$A,0)),"") -> Indira Balan | E846: =IFERROR(INDEX(Customers!$J:$J,MATCH(C846,Customers!$A:$A,0)),"") -> Bronze | F846: PRD003 | G846: =IFERROR(INDEX(Products!$B:$B,MATCH(F846,Products!$A:$A,0)),"") -> Harvest Gold Buns Combo | H846: =IFERROR(INDEX(Products!$C:$C,MATCH(F846,Products!$A:$A,0)),"") -> Bakery | I846: STR040 | J846: =IFERROR(INDEX(Stores!$B:$B,MATCH(I846,Stores!$A:$A,0)),"") -> FreshMart Coimbatore Colony | K846: =IFERROR(INDEX(Stores!$D:$D,MATCH(I846,Stores!$A:$A,0)),"") -> West | L846: EMP0061 | M846: =IFERROR(INDEX(Employees!$B:$B,MATCH(L846,Employees!$A:$A,0)),"") -> Poornima Devi | N846: =IFERROR(INDEX(Employees!$D:$D,MATCH(L846,Employees!$A:$A,0)),"") -> Billing | O846: 3 | P846: 589.75 | Q846: 20 | R846: 353.85 | S846: 1627.71 | T846: 1030.95 | U846: 596.76 | V846: UPI | W846: Not Returned | X846: In-Store | Y846: 13:28 | Z846: Weekend
A847: INV100846 | B847: 45989 | C847: CUST0105 | D847: =IFERROR(INDEX(Customers!$B:$B,MATCH(C847,Customers!$A:$A,0)),"") -> Revathi Sekar | E847: =IFERROR(INDEX(Customers!$J:$J,MATCH(C847,Customers!$A:$A,0)),"") -> Silver | F847: PRD099 | G847: =IFERROR(INDEX(Products!$B:$B,MATCH(F847,Products!$A:$A,0)),"") -> Local Farm Fresh Vegetables 200g | H847: =IFERROR(INDEX(Products!$C:$C,MATCH(F847,Products!$A:$A,0)),"") -> Vegetables | I847: STR127 | J847: =IFERROR(INDEX(Stores!$B:$B,MATCH(I847,Stores!$A:$A,0)),"") -> FreshMart Surat Enclave | K847: =IFERROR(INDEX(Stores!$D:$D,MATCH(I847,Stores!$A:$A,0)),"") -> West | L847: EMP0341 | M847: =IFERROR(INDEX(Employees!$B:$B,MATCH(L847,Employees!$A:$A,0)),"") -> Indira Chandran | N847: =IFERROR(INDEX(Employees!$D:$D,MATCH(L847,Employees!$A:$A,0)),"") -> Billing | O847: 4 | P847: 401.06 | Q847: 0 | R847: 0 | S847: 1604.24 | T847: 1389.88 | U847: 214.36 | V847: Net Banking | W847: Not Returned | X847: In-Store | Y847: 14:50 | Z847: Weekday
A848: INV100847 | B848: 45943 | C848: CUST0479 | D848: =IFERROR(INDEX(Customers!$B:$B,MATCH(C848,Customers!$A:$A,0)),"") -> Hariharan Raj | E848: =IFERROR(INDEX(Customers!$J:$J,MATCH(C848,Customers!$A:$A,0)),"") -> Bronze | F848: PRD103 | G848: =IFERROR(INDEX(Products!$B:$B,MATCH(F848,Products!$A:$A,0)),"") -> Organic Fresh Fresh Vegetables Pack | H848: =IFERROR(INDEX(Products!$C:$C,MATCH(F848,Products!$A:$A,0)),"") -> Vegetables | I848: STR109 | J848: =IFERROR(INDEX(Stores!$B:$B,MATCH(I848,Stores!$A:$A,0)),"") -> FreshMart Mumbai Complex | K848: =IFERROR(INDEX(Stores!$D:$D,MATCH(I848,Stores!$A:$A,0)),"") -> West | L848: EMP0180 | M848: =IFERROR(INDEX(Employees!$B:$B,MATCH(L848,Employees!$A:$A,0)),"") -> Venkat Balan | N848: =IFERROR(INDEX(Employees!$D:$D,MATCH(L848,Employees!$A:$A,0)),"") -> Billing | O848: 1 | P848: 355.64 | Q848: 15 | R848: 53.35 | S848: 302.29 | T848: 303.41 | U848: -1.12 | V848: Credit Card | W848: Not Returned | X848: Mobile App | Y848: 16:31 | Z848: Weekday
A849: INV100848 | B849: 46047 | C849: CUST0448 | D849: =IFERROR(INDEX(Customers!$B:$B,MATCH(C849,Customers!$A:$A,0)),"") -> Sanjay Achari | E849: =IFERROR(INDEX(Customers!$J:$J,MATCH(C849,Customers!$A:$A,0)),"") -> Silver | F849: PRD116 | G849: =IFERROR(INDEX(Products!$B:$B,MATCH(F849,Products!$A:$A,0)),"") -> Aachi Basmati Rice 200g | H849: =IFERROR(INDEX(Products!$C:$C,MATCH(F849,Products!$A:$A,0)),"") -> Rice | I849: STR112 | J849: =IFERROR(INDEX(Stores!$B:$B,MATCH(I849,Stores!$A:$A,0)),"") -> FreshMart Surat Colony | K849: =IFERROR(INDEX(Stores!$D:$D,MATCH(I849,Stores!$A:$A,0)),"") -> West | L849: EMP0084 | M849: =IFERROR(INDEX(Employees!$B:$B,MATCH(L849,Employees!$A:$A,0)),"") -> Lakshmi Velan | N849: =IFERROR(INDEX(Employees!$D:$D,MATCH(L849,Employees!$A:$A,0)),"") -> Cashier | O849: 4 | P849: 150.04 | Q849: 5 | R849: 30.01 | S849: 655.67 | T849: 511.92 | U849: 143.75 | V849: Cash | W849: Not Returned | X849: In-Store | Y849: 11:33 | Z849: Weekend
A850: INV100849 | B850: 45939 | C850: CUST0059 | D850: =IFERROR(INDEX(Customers!$B:$B,MATCH(C850,Customers!$A:$A,0)),"") -> Banu Sharma | E850: =IFERROR(INDEX(Customers!$J:$J,MATCH(C850,Customers!$A:$A,0)),"") -> Bronze | F850: PRD057 | G850: =IFERROR(INDEX(Products!$B:$B,MATCH(F850,Products!$A:$A,0)),"") -> Parle Chocolates 500g | H850: =IFERROR(INDEX(Products!$C:$C,MATCH(F850,Products!$A:$A,0)),"") -> Snacks | I850: STR013 | J850: =IFERROR(INDEX(Stores!$B:$B,MATCH(I850,Stores!$A:$A,0)),"") -> FreshMart Tiruppur Extension | K850: =IFERROR(INDEX(Stores!$D:$D,MATCH(I850,Stores!$A:$A,0)),"") -> South | L850: EMP0043 | M850: =IFERROR(INDEX(Employees!$B:$B,MATCH(L850,Employees!$A:$A,0)),"") -> Suresh Reddy | N850: =IFERROR(INDEX(Employees!$D:$D,MATCH(L850,Employees!$A:$A,0)),"") -> Cashier | O850: 1 | P850: 317.99 | Q850: 10 | R850: 31.8 | S850: 286.19 | T850: 235.05 | U850: 51.14 | V850: Wallet | W850: Not Returned | X850: Mobile App | Y850: 19:57 | Z850: Weekday
A851: INV100850 | B851: 45932 | C851: CUST0052 | D851: =IFERROR(INDEX(Customers!$B:$B,MATCH(C851,Customers!$A:$A,0)),"") -> Janani Selvam | E851: =IFERROR(INDEX(Customers!$J:$J,MATCH(C851,Customers!$A:$A,0)),"") -> Gold | F851: PRD049 | G851: =IFERROR(INDEX(Products!$B:$B,MATCH(F851,Products!$A:$A,0)),"") -> Cadbury Chips 1kg | H851: =IFERROR(INDEX(Products!$C:$C,MATCH(F851,Products!$A:$A,0)),"") -> Snacks | I851: STR056 | J851: =IFERROR(INDEX(Stores!$B:$B,MATCH(I851,Stores!$A:$A,0)),"") -> FreshMart Bengaluru Junction | K851: =IFERROR(INDEX(Stores!$D:$D,MATCH(I851,Stores!$A:$A,0)),"") -> South | L851: EMP0315 | M851: =IFERROR(INDEX(Employees!$B:$B,MATCH(L851,Employees!$A:$A,0)),"") -> Mani Pandian | N851: =IFERROR(INDEX(Employees!$D:$D,MATCH(L851,Employees!$A:$A,0)),"") -> Sales | O851: 3 | P851: 421.14 | Q851: 15 | R851: 189.51 | S851: 1073.91 | T851: 926.82 | U851: 147.09 | V851: Net Banking | W851: Not Returned | X851: In-Store | Y851: 12:00 | Z851: Weekday
A852: INV100851 | B852: 46027 | C852: CUST0574 | D852: =IFERROR(INDEX(Customers!$B:$B,MATCH(C852,Customers!$A:$A,0)),"") -> Dhanush Nathan | E852: =IFERROR(INDEX(Customers!$J:$J,MATCH(C852,Customers!$A:$A,0)),"") -> Bronze | F852: PRD015 | G852: =IFERROR(INDEX(Products!$B:$B,MATCH(F852,Products!$A:$A,0)),"") -> Nestle Butter 250ml | H852: =IFERROR(INDEX(Products!$C:$C,MATCH(F852,Products!$A:$A,0)),"") -> Dairy | I852: STR048 | J852: =IFERROR(INDEX(Stores!$B:$B,MATCH(I852,Stores!$A:$A,0)),"") -> FreshMart Bengaluru Square | K852: =IFERROR(INDEX(Stores!$D:$D,MATCH(I852,Stores!$A:$A,0)),"") -> South | L852: EMP0312 | M852: =IFERROR(INDEX(Employees!$B:$B,MATCH(L852,Employees!$A:$A,0)),"") -> Vasanthi Chettiar | N852: =IFERROR(INDEX(Employees!$D:$D,MATCH(L852,Employees!$A:$A,0)),"") -> Sales | O852: 1 | P852: 459.58 | Q852: 0 | R852: 0 | S852: 459.58 | T852: 386.89 | U852: 72.69 | V852: Wallet | W852: Not Returned | X852: In-Store | Y852: 10:33 | Z852: Weekday
A853: INV100852 | B853: 45962 | C853: CUST0672 | D853: =IFERROR(INDEX(Customers!$B:$B,MATCH(C853,Customers!$A:$A,0)),"") -> Chitra Devi | E853: =IFERROR(INDEX(Customers!$J:$J,MATCH(C853,Customers!$A:$A,0)),"") -> Silver | F853: PRD011 | G853: =IFERROR(INDEX(Products!$B:$B,MATCH(F853,Products!$A:$A,0)),"") -> Britannia Rusk 1L | H853: =IFERROR(INDEX(Products!$C:$C,MATCH(F853,Products!$A:$A,0)),"") -> Bakery | I853: STR157 | J853: =IFERROR(INDEX(Stores!$B:$B,MATCH(I853,Stores!$A:$A,0)),"") -> FreshMart Lucknow Extension | K853: =IFERROR(INDEX(Stores!$D:$D,MATCH(I853,Stores!$A:$A,0)),"") -> North | L853: EMP0297 | M853: =IFERROR(INDEX(Employees!$B:$B,MATCH(L853,Employees!$A:$A,0)),"") -> Kishore Naidu | N853: =IFERROR(INDEX(Employees!$D:$D,MATCH(L853,Employees!$A:$A,0)),"") -> Sales | O853: 5 | P853: 168.36 | Q853: 5 | R853: 42.09 | S853: 919.67 | T853: 511.15 | U853: 408.52 | V853: Net Banking | W853: Not Returned | X853: In-Store | Y853: 15:16 | Z853: Weekend
A854: INV100853 | B854: 45886 | C854: CUST0058 | D854: =IFERROR(INDEX(Customers!$B:$B,MATCH(C854,Customers!$A:$A,0)),"") -> Tara Devi | E854: =IFERROR(INDEX(Customers!$J:$J,MATCH(C854,Customers!$A:$A,0)),"") -> Gold | F854: PRD031 | G854: =IFERROR(INDEX(Products!$B:$B,MATCH(F854,Products!$A:$A,0)),"") -> Nescafe Coffee Pack | H854: =IFERROR(INDEX(Products!$C:$C,MATCH(F854,Products!$A:$A,0)),"") -> Beverages | I854: STR072 | J854: =IFERROR(INDEX(Stores!$B:$B,MATCH(I854,Stores!$A:$A,0)),"") -> FreshMart Salem Point | K854: =IFERROR(INDEX(Stores!$D:$D,MATCH(I854,Stores!$A:$A,0)),"") -> South | L854: EMP0124 | M854: =IFERROR(INDEX(Employees!$B:$B,MATCH(L854,Employees!$A:$A,0)),"") -> Vijay Pandian | N854: =IFERROR(INDEX(Employees!$D:$D,MATCH(L854,Employees!$A:$A,0)),"") -> Sales | O854: 7 | P854: 381.68 | Q854: 0 | R854: 0 | S854: 3072.52 | T854: 1902.46 | U854: 1170.06 | V854: Net Banking | W854: Not Returned | X854: Online | Y854: 14:48 | Z854: Weekend
A855: INV100854 | B855: 45957 | C855: CUST0507 | D855: =IFERROR(INDEX(Customers!$B:$B,MATCH(C855,Customers!$A:$A,0)),"") -> Kamala Iyer | E855: =IFERROR(INDEX(Customers!$J:$J,MATCH(C855,Customers!$A:$A,0)),"") -> Silver | F855: PRD107 | G855: =IFERROR(INDEX(Products!$B:$B,MATCH(F855,Products!$A:$A,0)),"") -> Aachi Idli Rice Combo | H855: =IFERROR(INDEX(Products!$C:$C,MATCH(F855,Products!$A:$A,0)),"") -> Rice | I855: STR069 | J855: =IFERROR(INDEX(Stores!$B:$B,MATCH(I855,Stores!$A:$A,0)),"") -> FreshMart Madurai Gardens | K855: =IFERROR(INDEX(Stores!$D:$D,MATCH(I855,Stores!$A:$A,0)),"") -> South | L855: EMP0042 | M855: =IFERROR(INDEX(Employees!$B:$B,MATCH(L855,Employees!$A:$A,0)),"") -> Nirmala Venkataraman | N855: =IFERROR(INDEX(Employees!$D:$D,MATCH(L855,Employees!$A:$A,0)),"") -> Sales | O855: 3 | P855: 405.1 | Q855: 10 | R855: 121.53 | S855: 1093.77 | T855: 1045.23 | U855: 48.54 | V855: Wallet | W855: Not Returned | X855: In-Store | Y855: 16:07 | Z855: Weekday
A856: INV100855 | B856: 45901 | C856: CUST0293 | D856: =IFERROR(INDEX(Customers!$B:$B,MATCH(C856,Customers!$A:$A,0)),"") -> Suresh Chandran | E856: =IFERROR(INDEX(Customers!$J:$J,MATCH(C856,Customers!$A:$A,0)),"") -> Gold | F856: PRD011 | G856: =IFERROR(INDEX(Products!$B:$B,MATCH(F856,Products!$A:$A,0)),"") -> Britannia Rusk 1L | H856: =IFERROR(INDEX(Products!$C:$C,MATCH(F856,Products!$A:$A,0)),"") -> Bakery | I856: STR007 | J856: =IFERROR(INDEX(Stores!$B:$B,MATCH(I856,Stores!$A:$A,0)),"") -> FreshMart Mysuru Towers | K856: =IFERROR(INDEX(Stores!$D:$D,MATCH(I856,Stores!$A:$A,0)),"") -> South | L856: EMP0233 | M856: =IFERROR(INDEX(Employees!$B:$B,MATCH(L856,Employees!$A:$A,0)),"") -> Sangeetha Balan | N856: =IFERROR(INDEX(Employees!$D:$D,MATCH(L856,Employees!$A:$A,0)),"") -> Sales | O856: 6 | P856: 188.72 | Q856: 10 | R856: 113.23 | S856: 1019.09 | T856: 613.38 | U856: 405.71 | V856: Cash | W856: Not Returned | X856: Online | Y856: 13:49 | Z856: Weekday
A857: INV100856 | B857: 45919 | C857: CUST0206 | D857: =IFERROR(INDEX(Customers!$B:$B,MATCH(C857,Customers!$A:$A,0)),"") -> Devi Venkataraman | E857: =IFERROR(INDEX(Customers!$J:$J,MATCH(C857,Customers!$A:$A,0)),"") -> Gold | F857: PRD026 | G857: =IFERROR(INDEX(Products!$B:$B,MATCH(F857,Products!$A:$A,0)),"") -> Nescafe Coffee 1kg | H857: =IFERROR(INDEX(Products!$C:$C,MATCH(F857,Products!$A:$A,0)),"") -> Beverages | I857: STR041 | J857: =IFERROR(INDEX(Stores!$B:$B,MATCH(I857,Stores!$A:$A,0)),"") -> FreshMart Tiruppur Colony | K857: =IFERROR(INDEX(Stores!$D:$D,MATCH(I857,Stores!$A:$A,0)),"") -> South | L857: EMP0097 | M857: =IFERROR(INDEX(Employees!$B:$B,MATCH(L857,Employees!$A:$A,0)),"") -> Hari Pandian | N857: =IFERROR(INDEX(Employees!$D:$D,MATCH(L857,Employees!$A:$A,0)),"") -> Billing | O857: 7 | P857: 374.25 | Q857: 10 | R857: 261.98 | S857: 2357.77 | T857: 1730.75 | U857: 627.02 | V857: UPI | W857: Not Returned | X857: In-Store | Y857: 19:47 | Z857: Weekday
... A1757: INV101756 | B1757: 46019 | C1757: CUST0341 | D1757: =IFERROR(INDEX(Customers!$B:$B,MATCH(C1757,Customers!$A:$A,0)),"") -> Elango Sekar | E1757: =IFERROR(INDEX(Customers!$J:$J,MATCH(C1757,Customers!$A:$A,0)),"") -> Silver | F1757: PRD030 | G1757: =IFERROR(INDEX(Products!$B:$B,MATCH(F1757,Products!$A:$A,0)),"") -> Nescafe Tea Combo | H1757: =IFERROR(INDEX(Products!$C:$C,MATCH(F1757,Products!$A:$A,0)),"") -> Beverages | I1757: STR071 | J1757: =IFERROR(INDEX(Stores!$B:$B,MATCH(I1757,Stores!$A:$A,0)),"") -> FreshMart Salem Crossing | K1757: =IFERROR(INDEX(Stores!$D:$D,MATCH(I1757,Stores!$A:$A,0)),"") -> South | L1757: EMP0144 | M1757: =IFERROR(INDEX(Employees!$B:$B,MATCH(L1757,Employees!$A:$A,0)),"") -> Chitra Nair | N1757: =IFERROR(INDEX(Employees!$D:$D,MATCH(L1757,Employees!$A:$A,0)),"") -> Cashier | O1757: 4 | P1757: 172.63 | Q1757: 0 | R1757: 0 | S1757: 794.1 | T1757: 568 | U1757: 226.1 | V1757: Cash | W1757: Not Returned | X1757: In-Store | Y1757: 15:58 | Z1757: Weekend
A1758: INV101757 | B1758: 45958 | C1758: CUST0145 | D1758: =IFERROR(INDEX(Customers!$B:$B,MATCH(C1758,Customers!$A:$A,0)),"") -> Sangeetha Pillai | E1758: =IFERROR(INDEX(Customers!$J:$J,MATCH(C1758,Customers!$A:$A,0)),"") -> Bronze | F1758: PRD031 | G1758: =IFERROR(INDEX(Products!$B:$B,MATCH(F1758,Products!$A:$A,0)),"") -> Nescafe Coffee Pack | H1758: =IFERROR(INDEX(Products!$C:$C,MATCH(F1758,Products!$A:$A,0)),"") -> Beverages | I1758: UNKNOWN | J1758: =IFERROR(INDEX(Stores!$B:$B,MATCH(I1758,Stores!$A:$A,0)),"") | K1758: South | L1758: EMP0151 | M1758: =IFERROR(INDEX(Employees!$B:$B,MATCH(L1758,Employees!$A:$A,0)),"") -> Arun Subramaniam | N1758: =IFERROR(INDEX(Employees!$D:$D,MATCH(L1758,Employees!$A:$A,0)),"") -> Billing | O1758: 2 | P1758: 342.46 | Q1758: 0 | R1758: 0 | S1758: 684.92 | T1758: 543.56 | U1758: 141.36 | V1758: Wallet | W1758: Not Returned | X1758: In-Store | Y1758: 10:47 | Z1758: Weekday
A1759: INV101758 | B1759: 46109 | C1759: CUST0558 | D1759: =IFERROR(INDEX(Customers!$B:$B,MATCH(C1759,Customers!$A:$A,0)),"") -> Banu Sekar | E1759: =IFERROR(INDEX(Customers!$J:$J,MATCH(C1759,Customers!$A:$A,0)),"") -> Silver | F1759: PRD031 | G1759: =IFERROR(INDEX(Products!$B:$B,MATCH(F1759,Products!$A:$A,0)),"") -> Nescafe Coffee Pack | H1759: =IFERROR(INDEX(Products!$C:$C,MATCH(F1759,Products!$A:$A,0)),"") -> Beverages | I1759: STR018 | J1759: =IFERROR(INDEX(Stores!$B:$B,MATCH(I1759,Stores!$A:$A,0)),"") -> FreshMart Hyderabad Main Road | K1759: =IFERROR(INDEX(Stores!$D:$D,MATCH(I1759,Stores!$A:$A,0)),"") -> South | L1759: EMP0308 | M1759: =IFERROR(INDEX(Employees!$B:$B,MATCH(L1759,Employees!$A:$A,0)),"") -> Thenmozhi Selvam | N1759: =IFERROR(INDEX(Employees!$D:$D,MATCH(L1759,Employees!$A:$A,0)),"") -> Cashier | O1759: 1 | P1759: 342.46 | Q1759: 0 | R1759: 0 | S1759: 393.83 | T1759: 271.78 | U1759: 122.05 | V1759: Wallet | W1759: Not Returned | X1759: In-Store | Y1759: 12:11 | Z1759: Weekend
A1760: INV101759 | B1760: 46002 | C1760: CUST0121 | D1760: =IFERROR(INDEX(Customers!$B:$B,MATCH(C1760,Customers!$A:$A,0)),"") -> Venkat Achari | E1760: =IFERROR(INDEX(Customers!$J:$J,MATCH(C1760,Customers!$A:$A,0)),"") -> Silver | F1760: PRD025 | G1760: =IFERROR(INDEX(Products!$B:$B,MATCH(F1760,Products!$A:$A,0)),"") -> Nescafe Soft Drinks Pack | H1760: =IFERROR(INDEX(Products!$C:$C,MATCH(F1760,Products!$A:$A,0)),"") -> Beverages | I1760: STR064 | J1760: =IFERROR(INDEX(Stores!$B:$B,MATCH(I1760,Stores!$A:$A,0)),"") -> FreshMart Kochi Extension | K1760: =IFERROR(INDEX(Stores!$D:$D,MATCH(I1760,Stores!$A:$A,0)),"") -> South | L1760: EMP0228 | M1760: =IFERROR(INDEX(Employees!$B:$B,MATCH(L1760,Employees!$A:$A,0)),"") -> Poornima Naidu | N1760: =IFERROR(INDEX(Employees!$D:$D,MATCH(L1760,Employees!$A:$A,0)),"") -> Sales | O1760: 4 | P1760: 383.51 | Q1760: 0 | R1760: 0 | S1760: 1534.04 | T1760: 1143.6 | U1760: 390.44 | V1760: Debit Card | W1760: Not Returned | X1760: In-Store | Y1760: 17:35 | Z1760: Weekday
A1761: INV101760 | B1761: 45981 | C1761: CUST0251 | D1761: =IFERROR(INDEX(Customers!$B:$B,MATCH(C1761,Customers!$A:$A,0)),"") -> Yogesh Devi | E1761: =IFERROR(INDEX(Customers!$J:$J,MATCH(C1761,Customers!$A:$A,0)),"") -> Silver | F1761: PRD135 | G1761: =IFERROR(INDEX(Products!$B:$B,MATCH(F1761,Products!$A:$A,0)),"") -> MDH Whole Spices 1L | H1761: =IFERROR(INDEX(Products!$C:$C,MATCH(F1761,Products!$A:$A,0)),"") -> Masala | I1761: STR046 | J1761: =IFERROR(INDEX(Stores!$B:$B,MATCH(I1761,Stores!$A:$A,0)),"") -> FreshMart Mysuru Colony | K1761: =IFERROR(INDEX(Stores!$D:$D,MATCH(I1761,Stores!$A:$A,0)),"") -> South | L1761: EMP0087 | M1761: =IFERROR(INDEX(Employees!$B:$B,MATCH(L1761,Employees!$A:$A,0)),"") -> Nagarajan Rao | N1761: =IFERROR(INDEX(Employees!$D:$D,MATCH(L1761,Employees!$A:$A,0)),"") -> Sales | O1761: 5 | P1761: 379.12 | Q1761: 5 | R1761: 94.78 | S1761: 1800.82 | T1761: 1465.25 | U1761: 335.57 | V1761: Credit Card | W1761: Not Returned | X1761: Online | Y1761: 14:58 | Z1761: Weekday
A1762: INV101761 | B1762: 46009 | C1762: CUST0135 | D1762: =IFERROR(INDEX(Customers!$B:$B,MATCH(C1762,Customers!$A:$A,0)),"") -> Pandi Velan | E1762: =IFERROR(INDEX(Customers!$J:$J,MATCH(C1762,Customers!$A:$A,0)),"") -> Bronze | F1762: PRD057 | G1762: =IFERROR(INDEX(Products!$B:$B,MATCH(F1762,Products!$A:$A,0)),"") -> Parle Chocolates 500g | H1762: =IFERROR(INDEX(Products!$C:$C,MATCH(F1762,Products!$A:$A,0)),"") -> Snacks | I1762: STR174 | J1762: =IFERROR(INDEX(Stores!$B:$B,MATCH(I1762,Stores!$A:$A,0)),"") -> FreshMart Guwahati Colony | K1762: =IFERROR(INDEX(Stores!$D:$D,MATCH(I1762,Stores!$A:$A,0)),"") -> East | L1762: EMP0266 | M1762: =IFERROR(INDEX(Employees!$B:$B,MATCH(L1762,Employees!$A:$A,0)),"") -> Bhuvana Iyer | N1762: =IFERROR(INDEX(Employees!$D:$D,MATCH(L1762,Employees!$A:$A,0)),"") -> Billing | O1762: 3 | P1762: 317.99 | Q1762: 0 | R1762: 0 | S1762: 953.97 | T1762: 705.15 | U1762: 248.82 | V1762: Debit Card | W1762: Not Returned | X1762: In-Store | Y1762: 18:49 | Z1762: Weekday
A1763: INV101762 | B1763: 45754 | C1763: CUST0509 | D1763: =IFERROR(INDEX(Customers!$B:$B,MATCH(C1763,Customers!$A:$A,0)),"") -> Harini Chandran | E1763: =IFERROR(INDEX(Customers!$J:$J,MATCH(C1763,Customers!$A:$A,0)),"") -> Gold | F1763: PRD054 | G1763: =IFERROR(INDEX(Products!$B:$B,MATCH(F1763,Products!$A:$A,0)),"") -> Lays Namkeen 2kg | H1763: =IFERROR(INDEX(Products!$C:$C,MATCH(F1763,Products!$A:$A,0)),"") -> Snacks | I1763: STR139 | J1763: =IFERROR(INDEX(Stores!$B:$B,MATCH(I1763,Stores!$A:$A,0)),"") -> FreshMart Nagpur Colony | K1763: =IFERROR(INDEX(Stores!$D:$D,MATCH(I1763,Stores!$A:$A,0)),"") -> West | L1763: EMP0242 | M1763: =IFERROR(INDEX(Employees!$B:$B,MATCH(L1763,Employees!$A:$A,0)),"") -> Sudha Iyer | N1763: =IFERROR(INDEX(Employees!$D:$D,MATCH(L1763,Employees!$A:$A,0)),"") -> Inventory | O1763: 7 | P1763: 598.7 | Q1763: 20 | R1763: 838.18 | S1763: 3352.72 | T1763: 2654.33 | U1763: 698.39 | V1763: Credit Card | W1763: Not Returned | X1763: In-Store | Y1763: 12:35 | Z1763: Weekday
A1764: INV101763 | B1764: 45905 | C1764: CUST0071 | D1764: =IFERROR(INDEX(Customers!$B:$B,MATCH(C1764,Customers!$A:$A,0)),"") -> Venkat Iyer | E1764: =IFERROR(INDEX(Customers!$J:$J,MATCH(C1764,Customers!$A:$A,0)),"") -> Silver | F1764: PRD008 | G1764: =IFERROR(INDEX(Products!$B:$B,MATCH(F1764,Products!$A:$A,0)),"") -> Britannia Cookies 200g | H1764: =IFERROR(INDEX(Products!$C:$C,MATCH(F1764,Products!$A:$A,0)),"") -> Bakery | I1764: STR172 | J1764: =IFERROR(INDEX(Stores!$B:$B,MATCH(I1764,Stores!$A:$A,0)),"") -> FreshMart Guwahati Heights | K1764: =IFERROR(INDEX(Stores!$D:$D,MATCH(I1764,Stores!$A:$A,0)),"") -> East | L1764: EMP0081 | M1764: =IFERROR(INDEX(Employees!$B:$B,MATCH(L1764,Employees!$A:$A,0)),"") -> Radha Selvam | N1764: =IFERROR(INDEX(Employees!$D:$D,MATCH(L1764,Employees!$A:$A,0)),"") -> Sales | O1764: 5 | P1764: 455.79 | Q1764: 0 | R1764: 0 | S1764: 2278.95 | T1764: 1414.4 | U1764: 864.55 | V1764: Cash | W1764: Not Returned | X1764: In-Store | Y1764: 13:28 | Z1764: Weekday
A1765: INV101764 | B1765: 45947 | C1765: CUST0138 | D1765: =IFERROR(INDEX(Customers!$B:$B,MATCH(C1765,Customers!$A:$A,0)),"") -> Bhavani Gounder | E1765: =IFERROR(INDEX(Customers!$J:$J,MATCH(C1765,Customers!$A:$A,0)),"") -> Bronze | F1765: PRD029 | G1765: =IFERROR(INDEX(Products!$B:$B,MATCH(F1765,Products!$A:$A,0)),"") -> Pepsi Tea 200g | H1765: =IFERROR(INDEX(Products!$C:$C,MATCH(F1765,Products!$A:$A,0)),"") -> Beverages | I1765: STR103 | J1765: =IFERROR(INDEX(Stores!$B:$B,MATCH(I1765,Stores!$A:$A,0)),"") -> FreshMart Surat Extension | K1765: =IFERROR(INDEX(Stores!$D:$D,MATCH(I1765,Stores!$A:$A,0)),"") -> West | L1765: EMP0251 | M1765: =IFERROR(INDEX(Employees!$B:$B,MATCH(L1765,Employees!$A:$A,0)),"") -> Ishwarya Pillai | N1765: =IFERROR(INDEX(Employees!$D:$D,MATCH(L1765,Employees!$A:$A,0)),"") -> Cashier | O1765: 4 | P1765: 332.73 | Q1765: 15 | R1765: 199.64 | S1765: 1131.28 | T1765: 1044.88 | U1765: 86.4 | V1765: Debit Card | W1765: Not Returned | X1765: In-Store | Y1765: 21:05 | Z1765: Weekday
A1766: INV101765 | B1766: 46064 | C1766: CUST0554 | D1766: =IFERROR(INDEX(Customers!$B:$B,MATCH(C1766,Customers!$A:$A,0)),"") -> Nirmala Chandran | E1766: =IFERROR(INDEX(Customers!$J:$J,MATCH(C1766,Customers!$A:$A,0)),"") -> Silver | F1766: PRD004 | G1766: =IFERROR(INDEX(Products!$B:$B,MATCH(F1766,Products!$A:$A,0)),"") -> Britannia Buns 2kg | H1766: =IFERROR(INDEX(Products!$C:$C,MATCH(F1766,Products!$A:$A,0)),"") -> Bakery | I1766: STR006 | J1766: =IFERROR(INDEX(Stores!$B:$B,MATCH(I1766,Stores!$A:$A,0)),"") -> FreshMart Mysuru Junction | K1766: =IFERROR(INDEX(Stores!$D:$D,MATCH(I1766,Stores!$A:$A,0)),"") -> South | L1766: EMP0265 | M1766: =IFERROR(INDEX(Employees!$B:$B,MATCH(L1766,Employees!$A:$A,0)),"") -> Padma Subramaniam | N1766: =IFERROR(INDEX(Employees!$D:$D,MATCH(L1766,Employees!$A:$A,0)),"") -> Operations | O1766: 2 | P1766: 398.25 | Q1766: 10 | R1766: 79.65 | S1766: 716.85 | T1766: 473.08 | U1766: 243.77 | V1766: UPI | W1766: Not Returned | X1766: In-Store | Y1766: 13:22 | Z1766: Weekday
A1767: INV101766 | B1767: 45832 | C1767: CUST0442 | D1767: =IFERROR(INDEX(Customers!$B:$B,MATCH(C1767,Customers!$A:$A,0)),"") -> Kamala Rao | E1767: =IFERROR(INDEX(Customers!$J:$J,MATCH(C1767,Customers!$A:$A,0)),"") -> Silver | F1767: PRD055 | G1767: =IFERROR(INDEX(Products!$B:$B,MATCH(F1767,Products!$A:$A,0)),"") -> Cadbury Biscuits Pack | H1767: =IFERROR(INDEX(Products!$C:$C,MATCH(F1767,Products!$A:$A,0)),"") -> Snacks | I1767: STR019 | J1767: =IFERROR(INDEX(Stores!$B:$B,MATCH(I1767,Stores!$A:$A,0)),"") -> FreshMart Hyderabad Heights | K1767: =IFERROR(INDEX(Stores!$D:$D,MATCH(I1767,Stores!$A:$A,0)),"") -> South | L1767: EMP0064 | M1767: =IFERROR(INDEX(Employees!$B:$B,MATCH(L1767,Employees!$A:$A,0)),"") -> Sanjay Venkataraman | N1767: =IFERROR(INDEX(Employees!$D:$D,MATCH(L1767,Employees!$A:$A,0)),"") -> Cashier | O1767: 3 | P1767: 125.15 | Q1767: 20 | R1767: 75.09 | S1767: 300.36 | T1767: 287.1 | U1767: 13.26 | V1767: Cash | W1767: Not Returned | X1767: In-Store | Y1767: 10:45 | Z1767: Weekday
A1768: INV101767 | B1768: 46005 | C1768: CUST0561 | D1768: =IFERROR(INDEX(Customers!$B:$B,MATCH(C1768,Customers!$A:$A,0)),"") -> Usha Balan | E1768: =IFERROR(INDEX(Customers!$J:$J,MATCH(C1768,Customers!$A:$A,0)),"") -> Bronze | F1768: PRD004 | G1768: =IFERROR(INDEX(Products!$B:$B,MATCH(F1768,Products!$A:$A,0)),"") -> Britannia Buns 2kg | H1768: =IFERROR(INDEX(Products!$C:$C,MATCH(F1768,Products!$A:$A,0)),"") -> Bakery | I1768: STR059 | J1768: =IFERROR(INDEX(Stores!$B:$B,MATCH(I1768,Stores!$A:$A,0)),"") -> FreshMart Coimbatore Plaza | K1768: =IFERROR(INDEX(Stores!$D:$D,MATCH(I1768,Stores!$A:$A,0)),"") -> South | L1768: EMP0160 | M1768: =IFERROR(INDEX(Employees!$B:$B,MATCH(L1768,Employees!$A:$A,0)),"") -> Sangeetha Pillai | N1768: =IFERROR(INDEX(Employees!$D:$D,MATCH(L1768,Employees!$A:$A,0)),"") -> Sales | O1768: 4 | P1768: 398.25 | Q1768: 0 | R1768: 0 | S1768: 1831.95 | T1768: 946.16 | U1768: 885.79 | V1768: Cash | W1768: Not Returned | X1768: Mobile App | Y1768: 12:56 | Z1768: Weekend
A1769: INV101768 | B1769: 45882 | C1769: CUST0633 | D1769: =IFERROR(INDEX(Customers!$B:$B,MATCH(C1769,Customers!$A:$A,0)),"") -> Devi Mudaliar | E1769: =IFERROR(INDEX(Customers!$J:$J,MATCH(C1769,Customers!$A:$A,0)),"") -> Gold | F1769: PRD102 | G1769: =IFERROR(INDEX(Products!$B:$B,MATCH(F1769,Products!$A:$A,0)),"") -> Local Farm Fresh Vegetables 200g v2 | H1769: =IFERROR(INDEX(Products!$C:$C,MATCH(F1769,Products!$A:$A,0)),"") -> Vegetables | I1769: STR002 | J1769: =IFERROR(INDEX(Stores!$B:$B,MATCH(I1769,Stores!$A:$A,0)),"") -> FreshMart Tiruppur Bypass | K1769: =IFERROR(INDEX(Stores!$D:$D,MATCH(I1769,Stores!$A:$A,0)),"") -> South | L1769: EMP0060 | M1769: =IFERROR(INDEX(Employees!$B:$B,MATCH(L1769,Employees!$A:$A,0)),"") -> Venkat Gupta | N1769: =IFERROR(INDEX(Employees!$D:$D,MATCH(L1769,Employees!$A:$A,0)),"") -> Sales | O1769: 3 | P1769: 447.33 | Q1769: 0 | R1769: 0 | S1769: 1341.99 | T1769: 1022.7 | U1769: 319.29 | V1769: Debit Card | W1769: Not Returned | X1769: In-Store | Y1769: 14:58 | Z1769: Weekday
...

Sheet Cleaning_Log
A1: Table | B1: Issue | C1: Action Taken | D1: Rows Affected
A2: Customers | B2: Redundant name-fragment columns (Unnamed: 1-3) | C2: Dropped (Customer_Name already complete) | D2: 3
A3: Customers | B3: Missing Customer_Name | C3: Filled with 'Unknown' (not recoverable) | D3: 8
A4: Customers | B4: Inconsistent Gender values (case/typos: M, MALE, Femle...) | C4: Standardized to Male/Female | D4: 9
A5: Customers | B5: Inconsistent Membership values (Gld, GOLD, silver...) | C5: Standardized to Bronze/Silver/Gold | D5: 8
A6: Customers | B6: Missing Region | C6: Imputed from City (using other customers in same city) | D6: 5
A7: Customers | B7: Malformed emails (missing "@", "#" used instead) | C7: Reconstructed valid email address | D7: 8
A8: Customers | B8: Fully duplicate rows | C8: None found | D8: 0
A9: Employees | B9: Missing Employee_Name | C9: Filled with 'Unknown' (not recoverable) | D9: 3
A10: Employees | B10: Missing Store_ID | C10: Filled with 'UNASSIGNED' (flagged, not recoverable) | D10: 3
A11: Employees | B11: Inconsistent Gender values | C11: Standardized to Male/Female | D11: 5
A12: Employees | B12: Inconsistent Employment_Status (actiive, Actve, In-Active...) | C12: Standardized to Active/Inactive | D12: 4
A13: Employees | B13: Salary stored as text with "Rs" prefix | C13: Stripped currency prefix, converted to numeric | D13: 5
... A39: Sales_Transactions | B39: Fully duplicate rows | C39: None found | D39: 0

Sheet Store Managers — Regional Sales
G17: Store_Type | H17: All
G19: Row Labels | H19: Sum of Sales_Amount | I19: Sum of Monthly_Target
G20: East | H20: 62655.19 | I20: 31565725
G21: North | H21: 248896.27 | I21: 79129132
G22: South | H22: 1889516.3 | I22: 178318569
G23: West | H23: 690929.95 | I23: 73232042
G24: (blank) | H24: 2665.21
G25: Grand Total | H25: 2894662.9 | I25: 362245468

Sheet Product Managers — Category & B
A1: Brand | B1: All
A3: Row Labels | B3: Sum of Sales_Amount | C3: Sum of Profit
B4: 8137.18 | C4: 1767.84
A5: Bakery | B5: 365248.49 | C5: 149305.74
A6: Beverages | B6: 474862.21 | C6: 117031.27
A7: Cleaning | B7: 97873.45 | C7: 27123.8
A8: Dairy | B8: 354284.25 | C8: 74650.33
A9: Frozen Foods | B9: 57671.03 | C9: 8817.43
A10: Fruits | B10: 238749.9 | C10: 46573.77
A11: Household | B11: 144591.68 | C11: 35467.75
A12: Masala | B12: 154565.18 | C12: 41220.14
A13: Oil | B13: 124504.98 | C13: 19200.85
A14: Personal Care | B14: 192624.16 | C14: 61117.96
A15: Rice | B15: 170852.24 | C15: 30185.16
A16: Snacks | B16: 292184.43 | C16: 84119.62
... A18: Grand Total | B18: 2894662.9 | C18: 737358.89

Sheet Marketing   Customer Success — 
A1: Gender | B1: All
A3: Row Labels | B3: Average of Sales_Amount
A4: Bronze | B4: 720.76285
A5: Gold | B5: 1672.7885
A6: Silver | B6: 851.22086
A7: (blank) | B7: 1490.7413
A8: Grand Total | B8: 1157.8652

Sheet Operations — Sales Channel x Pa
A1: Return_Status | B1: All
B3: Column Labels
B4: Cash | D4: Credit Card | F4: Debit Card | H4: Net Banking | J4: UPI | L4: Wallet | N4: Total Sum of Sales_Amount | O4: Total Count of Invoice_Number
A5: Row Labels | B5: Sum of Sales_Amount | C5: Count of Invoice_Number | D5: Sum of Sales_Amount | E5: Count of Invoice_Number | F5: Sum of Sales_Amount | G5: Count of Invoice_Number | H5: Sum of Sales_Amount | I5: Count of Invoice_Number | J5: Sum of Sales_Amount | K5: Count of Invoice_Number | L5: Sum of Sales_Amount | M5: Count of Invoice_Number
A6: In-Store | B6: 285020.69 | C6: 270 | D6: 331604.41 | E6: 288 | F6: 344988.17 | G6: 289 | H6: 315986.08 | I6: 276 | J6: 367729.3 | K6: 311 | L6: 345250.8 | M6: 304 | N6: 1990579.4 | O6: 1738
A7: Mobile App | B7: 49355.03 | C7: 39 | D7: 45664.12 | E7: 40 | F7: 52873.66 | G7: 43 | H7: 44660.01 | I7: 34 | J7: 50789.54 | K7: 42 | L7: 46114.37 | M7: 39 | N7: 289456.73 | O7: 237
A8: Online | B8: 104833.58 | C8: 80 | D8: 100764.13 | E8: 91 | F8: 94813.13 | G8: 88 | H8: 83413.49 | I8: 78 | J8: 131507.61 | K8: 104 | L8: 99294.78 | M8: 84 | N8: 614626.72 | O8: 525
A9: Grand Total | B9: 439209.3 | C9: 389 | D9: 478032.66 | E9: 419 | F9: 492674.96 | G9: 420 | H9: 444059.58 | I9: 388 | J9: 550026.45 | K9: 457 | L9: 490659.95 | M9: 427 | N9: 2894662.9 | O9: 2500

Sheet Executive   Finance — Sales Tre
A1: Day_Type | B1: All
A3: Row Labels | B3: Sum of Sales_Amount | C3: Sum of Profit
A4: Jan | B4: 121730.91 | C4: 29980.87
A5: Feb | B5: 169954.08 | C5: 43151.69
A6: Mar | B6: 243357.27 | C6: 61610.78
A7: Apr | B7: 195249.44 | C7: 50155.37
A8: May | B8: 225062.29 | C8: 61161.92
A9: Jun | B9: 226577.54 | C9: 58096.27
A10: Jul | B10: 177176.06 | C10: 42067
A11: Aug | B11: 200032.75 | C11: 49379.88
A12: Sep | B12: 241049.36 | C12: 58943.03
A13: Oct | B13: 447130.54 | C13: 115133.04
A14: Nov | B14: 306837.19 | C14: 79014.61
A15: Dec | B15: 340505.47 | C15: 88664.43
A16: Grand Total | B16: 2894662.9 | C16: 737358.89

Sheet DASHBOARD
A1: FRESHMART PERFORMANCE DASHBOARD
